[2023-12-28T12:44:27.113+0000] {taskinstance.py:1159} INFO - Dependencies all met for dep_context=non-requeueable deps ti=<TaskInstance: dag_with_postgres_operator_v03.insert_records scheduled__2023-12-27T00:00:00+00:00 [queued]>
[2023-12-28T12:44:27.127+0000] {taskinstance.py:1159} INFO - Dependencies all met for dep_context=requeueable deps ti=<TaskInstance: dag_with_postgres_operator_v03.insert_records scheduled__2023-12-27T00:00:00+00:00 [queued]>
[2023-12-28T12:44:27.128+0000] {taskinstance.py:1361} INFO - Starting attempt 1 of 6
[2023-12-28T12:44:27.249+0000] {taskinstance.py:1382} INFO - Executing <Task(PythonOperator): insert_records> on 2023-12-27 00:00:00+00:00
[2023-12-28T12:44:27.256+0000] {standard_task_runner.py:57} INFO - Started process 389 to run task
[2023-12-28T12:44:27.260+0000] {standard_task_runner.py:84} INFO - Running: ['***', 'tasks', 'run', 'dag_with_postgres_operator_v03', 'insert_records', 'scheduled__2023-12-27T00:00:00+00:00', '--job-id', '5', '--raw', '--subdir', 'DAGS_FOLDER/dag_with_postgres_operator.py', '--cfg-path', '/tmp/tmp1qgum_fl']
[2023-12-28T12:44:27.263+0000] {standard_task_runner.py:85} INFO - Job 5: Subtask insert_records
[2023-12-28T12:44:27.412+0000] {task_command.py:415} INFO - Running <TaskInstance: dag_with_postgres_operator_v03.insert_records scheduled__2023-12-27T00:00:00+00:00 [running]> on host 9b8290fc3c0d
[2023-12-28T12:44:27.597+0000] {taskinstance.py:1660} INFO - Exporting env vars: AIRFLOW_CTX_DAG_OWNER='***' AIRFLOW_CTX_DAG_ID='dag_with_postgres_operator_v03' AIRFLOW_CTX_TASK_ID='insert_records' AIRFLOW_CTX_EXECUTION_DATE='2023-12-27T00:00:00+00:00' AIRFLOW_CTX_TRY_NUMBER='1' AIRFLOW_CTX_DAG_RUN_ID='scheduled__2023-12-27T00:00:00+00:00'
[2023-12-28T12:44:28.273+0000] {logging_mixin.py:151} INFO - <<<<<<<<<<start migrating data>>>>>>>>>>>>>>
[2023-12-28T12:44:28.289+0000] {taskinstance.py:1943} ERROR - Task failed with exception
Traceback (most recent call last):
  File "/home/airflow/.local/lib/python3.8/site-packages/sqlalchemy/engine/base.py", line 3371, in _wrap_pool_connect
    return fn()
  File "/home/airflow/.local/lib/python3.8/site-packages/sqlalchemy/pool/base.py", line 327, in connect
    return _ConnectionFairy._checkout(self)
  File "/home/airflow/.local/lib/python3.8/site-packages/sqlalchemy/pool/base.py", line 894, in _checkout
    fairy = _ConnectionRecord.checkout(pool)
  File "/home/airflow/.local/lib/python3.8/site-packages/sqlalchemy/pool/base.py", line 493, in checkout
    rec = pool._do_get()
  File "/home/airflow/.local/lib/python3.8/site-packages/sqlalchemy/pool/impl.py", line 146, in _do_get
    self._dec_overflow()
  File "/home/airflow/.local/lib/python3.8/site-packages/sqlalchemy/util/langhelpers.py", line 70, in __exit__
    compat.raise_(
  File "/home/airflow/.local/lib/python3.8/site-packages/sqlalchemy/util/compat.py", line 211, in raise_
    raise exception
  File "/home/airflow/.local/lib/python3.8/site-packages/sqlalchemy/pool/impl.py", line 143, in _do_get
    return self._create_connection()
  File "/home/airflow/.local/lib/python3.8/site-packages/sqlalchemy/pool/base.py", line 273, in _create_connection
    return _ConnectionRecord(self)
  File "/home/airflow/.local/lib/python3.8/site-packages/sqlalchemy/pool/base.py", line 388, in __init__
    self.__connect()
  File "/home/airflow/.local/lib/python3.8/site-packages/sqlalchemy/pool/base.py", line 691, in __connect
    pool.logger.debug("Error on connect(): %s", e)
  File "/home/airflow/.local/lib/python3.8/site-packages/sqlalchemy/util/langhelpers.py", line 70, in __exit__
    compat.raise_(
  File "/home/airflow/.local/lib/python3.8/site-packages/sqlalchemy/util/compat.py", line 211, in raise_
    raise exception
  File "/home/airflow/.local/lib/python3.8/site-packages/sqlalchemy/pool/base.py", line 686, in __connect
    self.dbapi_connection = connection = pool._invoke_creator(self)
  File "/home/airflow/.local/lib/python3.8/site-packages/sqlalchemy/engine/create.py", line 574, in connect
    return dialect.connect(*cargs, **cparams)
  File "/home/airflow/.local/lib/python3.8/site-packages/sqlalchemy/engine/default.py", line 598, in connect
    return self.dbapi.connect(*cargs, **cparams)
  File "/home/airflow/.local/lib/python3.8/site-packages/psycopg2/__init__.py", line 122, in connect
    conn = _connect(dsn, connection_factory=connection_factory, **kwasync)
psycopg2.OperationalError: connection to server at "host.docker.internal" (192.168.65.254), port 5432 failed: FATAL:  password authentication failed for user "postgres"


The above exception was the direct cause of the following exception:

Traceback (most recent call last):
  File "/home/airflow/.local/lib/python3.8/site-packages/airflow/operators/python.py", line 192, in execute
    return_value = self.execute_callable()
  File "/home/airflow/.local/lib/python3.8/site-packages/airflow/operators/python.py", line 209, in execute_callable
    return self.python_callable(*self.op_args, **self.op_kwargs)
  File "/opt/airflow/dags/dag_with_postgres_operator.py", line 26, in migrate_data
    df.to_sql("booking_record", con=engine, if_exists='replace',index_label='id')
  File "/home/airflow/.local/lib/python3.8/site-packages/pandas/core/generic.py", line 2878, in to_sql
    return sql.to_sql(
  File "/home/airflow/.local/lib/python3.8/site-packages/pandas/io/sql.py", line 768, in to_sql
    with pandasSQL_builder(con, schema=schema, need_transaction=True) as pandas_sql:
  File "/home/airflow/.local/lib/python3.8/site-packages/pandas/io/sql.py", line 832, in pandasSQL_builder
    return SQLDatabase(con, schema, need_transaction)
  File "/home/airflow/.local/lib/python3.8/site-packages/pandas/io/sql.py", line 1539, in __init__
    con = self.exit_stack.enter_context(con.connect())
  File "/home/airflow/.local/lib/python3.8/site-packages/sqlalchemy/engine/base.py", line 3325, in connect
    return self._connection_cls(self, close_with_result=close_with_result)
  File "/home/airflow/.local/lib/python3.8/site-packages/sqlalchemy/engine/base.py", line 96, in __init__
    else engine.raw_connection()
  File "/home/airflow/.local/lib/python3.8/site-packages/sqlalchemy/engine/base.py", line 3404, in raw_connection
    return self._wrap_pool_connect(self.pool.connect, _connection)
  File "/home/airflow/.local/lib/python3.8/site-packages/sqlalchemy/engine/base.py", line 3374, in _wrap_pool_connect
    Connection._handle_dbapi_exception_noconnection(
  File "/home/airflow/.local/lib/python3.8/site-packages/sqlalchemy/engine/base.py", line 2208, in _handle_dbapi_exception_noconnection
    util.raise_(
  File "/home/airflow/.local/lib/python3.8/site-packages/sqlalchemy/util/compat.py", line 211, in raise_
    raise exception
  File "/home/airflow/.local/lib/python3.8/site-packages/sqlalchemy/engine/base.py", line 3371, in _wrap_pool_connect
    return fn()
  File "/home/airflow/.local/lib/python3.8/site-packages/sqlalchemy/pool/base.py", line 327, in connect
    return _ConnectionFairy._checkout(self)
  File "/home/airflow/.local/lib/python3.8/site-packages/sqlalchemy/pool/base.py", line 894, in _checkout
    fairy = _ConnectionRecord.checkout(pool)
  File "/home/airflow/.local/lib/python3.8/site-packages/sqlalchemy/pool/base.py", line 493, in checkout
    rec = pool._do_get()
  File "/home/airflow/.local/lib/python3.8/site-packages/sqlalchemy/pool/impl.py", line 146, in _do_get
    self._dec_overflow()
  File "/home/airflow/.local/lib/python3.8/site-packages/sqlalchemy/util/langhelpers.py", line 70, in __exit__
    compat.raise_(
  File "/home/airflow/.local/lib/python3.8/site-packages/sqlalchemy/util/compat.py", line 211, in raise_
    raise exception
  File "/home/airflow/.local/lib/python3.8/site-packages/sqlalchemy/pool/impl.py", line 143, in _do_get
    return self._create_connection()
  File "/home/airflow/.local/lib/python3.8/site-packages/sqlalchemy/pool/base.py", line 273, in _create_connection
    return _ConnectionRecord(self)
  File "/home/airflow/.local/lib/python3.8/site-packages/sqlalchemy/pool/base.py", line 388, in __init__
    self.__connect()
  File "/home/airflow/.local/lib/python3.8/site-packages/sqlalchemy/pool/base.py", line 691, in __connect
    pool.logger.debug("Error on connect(): %s", e)
  File "/home/airflow/.local/lib/python3.8/site-packages/sqlalchemy/util/langhelpers.py", line 70, in __exit__
    compat.raise_(
  File "/home/airflow/.local/lib/python3.8/site-packages/sqlalchemy/util/compat.py", line 211, in raise_
    raise exception
  File "/home/airflow/.local/lib/python3.8/site-packages/sqlalchemy/pool/base.py", line 686, in __connect
    self.dbapi_connection = connection = pool._invoke_creator(self)
  File "/home/airflow/.local/lib/python3.8/site-packages/sqlalchemy/engine/create.py", line 574, in connect
    return dialect.connect(*cargs, **cparams)
  File "/home/airflow/.local/lib/python3.8/site-packages/sqlalchemy/engine/default.py", line 598, in connect
    return self.dbapi.connect(*cargs, **cparams)
  File "/home/airflow/.local/lib/python3.8/site-packages/psycopg2/__init__.py", line 122, in connect
    conn = _connect(dsn, connection_factory=connection_factory, **kwasync)
sqlalchemy.exc.OperationalError: (psycopg2.OperationalError) connection to server at "host.docker.internal" (192.168.65.254), port 5432 failed: FATAL:  password authentication failed for user "postgres"

(Background on this error at: https://sqlalche.me/e/14/e3q8)
[2023-12-28T12:44:28.805+0000] {taskinstance.py:1400} INFO - Marking task as UP_FOR_RETRY. dag_id=dag_with_postgres_operator_v03, task_id=insert_records, execution_date=20231227T000000, start_date=20231228T124427, end_date=20231228T124428
[2023-12-28T12:44:28.876+0000] {standard_task_runner.py:104} ERROR - Failed to execute job 5 for task insert_records ((psycopg2.OperationalError) connection to server at "host.docker.internal" (192.168.65.254), port 5432 failed: FATAL:  password authentication failed for user "postgres"

(Background on this error at: https://sqlalche.me/e/14/e3q8); 389)
[2023-12-28T12:44:28.920+0000] {local_task_job_runner.py:228} INFO - Task exited with return code 1
[2023-12-28T12:44:28.949+0000] {taskinstance.py:2784} INFO - 0 downstream tasks scheduled from follow-on schedule check
[2023-12-28T12:48:23.126+0000] {taskinstance.py:1159} INFO - Dependencies all met for dep_context=non-requeueable deps ti=<TaskInstance: dag_with_postgres_operator_v03.insert_records scheduled__2023-12-27T00:00:00+00:00 [queued]>
[2023-12-28T12:48:23.166+0000] {taskinstance.py:1159} INFO - Dependencies all met for dep_context=requeueable deps ti=<TaskInstance: dag_with_postgres_operator_v03.insert_records scheduled__2023-12-27T00:00:00+00:00 [queued]>
[2023-12-28T12:48:23.166+0000] {taskinstance.py:1361} INFO - Starting attempt 1 of 6
[2023-12-28T12:48:23.236+0000] {taskinstance.py:1382} INFO - Executing <Task(PythonOperator): insert_records> on 2023-12-27 00:00:00+00:00
[2023-12-28T12:48:23.253+0000] {standard_task_runner.py:57} INFO - Started process 503 to run task
[2023-12-28T12:48:23.258+0000] {standard_task_runner.py:84} INFO - Running: ['***', 'tasks', 'run', 'dag_with_postgres_operator_v03', 'insert_records', 'scheduled__2023-12-27T00:00:00+00:00', '--job-id', '7', '--raw', '--subdir', 'DAGS_FOLDER/dag_with_postgres_operator.py', '--cfg-path', '/tmp/tmp0fhzsq09']
[2023-12-28T12:48:23.271+0000] {standard_task_runner.py:85} INFO - Job 7: Subtask insert_records
[2023-12-28T12:48:23.416+0000] {task_command.py:415} INFO - Running <TaskInstance: dag_with_postgres_operator_v03.insert_records scheduled__2023-12-27T00:00:00+00:00 [running]> on host 9b8290fc3c0d
[2023-12-28T12:48:23.621+0000] {taskinstance.py:1660} INFO - Exporting env vars: AIRFLOW_CTX_DAG_OWNER='***' AIRFLOW_CTX_DAG_ID='dag_with_postgres_operator_v03' AIRFLOW_CTX_TASK_ID='insert_records' AIRFLOW_CTX_EXECUTION_DATE='2023-12-27T00:00:00+00:00' AIRFLOW_CTX_TRY_NUMBER='1' AIRFLOW_CTX_DAG_RUN_ID='scheduled__2023-12-27T00:00:00+00:00'
[2023-12-28T12:48:23.970+0000] {logging_mixin.py:151} INFO - <<<<<<<<<<start migrating data>>>>>>>>>>>>>>
[2023-12-28T12:48:24.797+0000] {logging_mixin.py:151} INFO - <<<<<<<<<<<<<<<<<<<completed>>>>>>>>>>>>>>>>
[2023-12-28T12:48:24.798+0000] {python.py:194} INFO - Done. Returned value was: None
[2023-12-28T12:48:24.812+0000] {taskinstance.py:1400} INFO - Marking task as SUCCESS. dag_id=dag_with_postgres_operator_v03, task_id=insert_records, execution_date=20231227T000000, start_date=20231228T124823, end_date=20231228T124824
[2023-12-28T12:48:25.002+0000] {local_task_job_runner.py:228} INFO - Task exited with return code 0
[2023-12-28T12:48:25.028+0000] {taskinstance.py:2784} INFO - 0 downstream tasks scheduled from follow-on schedule check
[2023-12-28T13:07:11.120+0000] {taskinstance.py:1159} INFO - Dependencies all met for dep_context=non-requeueable deps ti=<TaskInstance: dag_with_postgres_operator_v03.insert_records scheduled__2023-12-27T00:00:00+00:00 [queued]>
[2023-12-28T13:07:11.161+0000] {taskinstance.py:1159} INFO - Dependencies all met for dep_context=requeueable deps ti=<TaskInstance: dag_with_postgres_operator_v03.insert_records scheduled__2023-12-27T00:00:00+00:00 [queued]>
[2023-12-28T13:07:11.162+0000] {taskinstance.py:1361} INFO - Starting attempt 1 of 6
[2023-12-28T13:07:11.227+0000] {taskinstance.py:1382} INFO - Executing <Task(PythonOperator): insert_records> on 2023-12-27 00:00:00+00:00
[2023-12-28T13:07:11.236+0000] {standard_task_runner.py:57} INFO - Started process 1000 to run task
[2023-12-28T13:07:11.241+0000] {standard_task_runner.py:84} INFO - Running: ['***', 'tasks', 'run', 'dag_with_postgres_operator_v03', 'insert_records', 'scheduled__2023-12-27T00:00:00+00:00', '--job-id', '9', '--raw', '--subdir', 'DAGS_FOLDER/dag_with_postgres_operator.py', '--cfg-path', '/tmp/tmphyd60h99']
[2023-12-28T13:07:11.245+0000] {standard_task_runner.py:85} INFO - Job 9: Subtask insert_records
[2023-12-28T13:07:11.369+0000] {task_command.py:415} INFO - Running <TaskInstance: dag_with_postgres_operator_v03.insert_records scheduled__2023-12-27T00:00:00+00:00 [running]> on host 9b8290fc3c0d
[2023-12-28T13:07:11.580+0000] {taskinstance.py:1660} INFO - Exporting env vars: AIRFLOW_CTX_DAG_OWNER='***' AIRFLOW_CTX_DAG_ID='dag_with_postgres_operator_v03' AIRFLOW_CTX_TASK_ID='insert_records' AIRFLOW_CTX_EXECUTION_DATE='2023-12-27T00:00:00+00:00' AIRFLOW_CTX_TRY_NUMBER='1' AIRFLOW_CTX_DAG_RUN_ID='scheduled__2023-12-27T00:00:00+00:00'
[2023-12-28T13:07:11.836+0000] {logging_mixin.py:151} INFO - <<<<<<<<<<start migrating data>>>>>>>>>>>>>>
[2023-12-28T13:07:12.092+0000] {logging_mixin.py:151} INFO - <<<<<<<<<<<<<<<<<<<completed>>>>>>>>>>>>>>>>
[2023-12-28T13:07:12.093+0000] {python.py:194} INFO - Done. Returned value was: None
[2023-12-28T13:07:12.110+0000] {taskinstance.py:1400} INFO - Marking task as SUCCESS. dag_id=dag_with_postgres_operator_v03, task_id=insert_records, execution_date=20231227T000000, start_date=20231228T130711, end_date=20231228T130712
[2023-12-28T13:07:12.181+0000] {local_task_job_runner.py:228} INFO - Task exited with return code 0
[2023-12-28T13:07:12.296+0000] {taskinstance.py:2784} INFO - 0 downstream tasks scheduled from follow-on schedule check
